-------------------------------------------------------------        
[mysql_handler] [2024-09-03 14:32:06,182] [ERROR] > Error insert request
-------------------------------------------------------------        
[mysql_handler] [2024-09-03 14:40:21,292] [ERROR] > Error insert requestNot all parameters were used in the SQL statement
-------------------------------------------------------------        
[mysql_handler] [2024-09-03 14:41:35,281] [ERROR] > Error insert requeste=ProgrammingError(-1, 'Not all parameters were used in the SQL statement', None)
-------------------------------------------------------------        
[mysql_handler] [2024-09-03 14:44:41,497] [ERROR] > Error insert request: Not all parameters were used in the SQL statement
None
-------------------------------------------------------------        
[mysql_handler] [2024-09-03 14:48:39,765] [ERROR] > Error insert request: None

-------------------------------------------------------------        
[mysql_handler] [2024-09-03 14:49:09,035] [ERROR] > Error insert request: <traceback object at 0x000001270E4AA000>

-------------------------------------------------------------        
[mysql_handler] [2024-09-03 14:49:45,991] [ERROR] > Error insert request: <built-in method with_traceback of ProgrammingError object at 0x0000017A64A7A510>

-------------------------------------------------------------        
[mysql_handler] [2024-09-03 14:50:23,772] [ERROR] > Error insert request: <bound method Error.__str__ of ProgrammingError(-1, 'Not all parameters were used in the SQL statement', None)>

-------------------------------------------------------------        
[mysql_handler] [2024-09-03 14:51:37,689] [ERROR] > Error insert request: Exception for errors programming errors

-------------------------------------------------------------        
[mysql_handler] [2024-09-03 14:59:52,662] [ERROR] > Error insert request: Not all parameters were used in the SQL statement

-------------------------------------------------------------        
[mysql_handler] [2024-09-03 15:01:32,823] [ERROR] > Error insert request: Not all parameters were used in the SQL statement

-------------------------------------------------------------        
[mysql_handler] [2024-09-03 15:03:32,659] [ERROR] > Error insert request: Not all parameters were used in the SQL statement

-------------------------------------------------------------        
[mysql_handler] [2024-09-03 15:06:26,815] [ERROR] > Error insert request: Not all parameters were used in the SQL statement

-------------------------------------------------------------        
[mysql_handler] [2024-09-03 15:14:17,698] [ERROR] > Error insert request: Not all parameters were used in the SQL statement

-------------------------------------------------------------        
[mysql_handler] [2024-09-04 17:16:58,858] [ERROR] > Error insert request: Not all parameters were used in the SQL statement

-------------------------------------------------------------        
[mysql_handler] [2024-09-04 17:17:50,507] [ERROR] > Error insert request: Not all parameters were used in the SQL statement
Traceback (most recent call last):
  File "D:\myPy\xboxshop\parser\mysql_handler.py", line 30, in isert_or_update
    self.cursor.execute(sql, param)
  File "D:\myPy\gpt\venv\Lib\site-packages\mysql\connector\cursor_cext.py", line 352, in execute
    raise ProgrammingError(
mysql.connector.errors.ProgrammingError: Not all parameters were used in the SQL statement
-------------------------------------------------------------        
[mysql_handler] [2024-09-05 09:53:10,221] [ERROR] > Error insert request: Not all parameters were used in the SQL statement
Traceback (most recent call last):
  File "D:\myPy\xboxshop\parser\mysql_handler.py", line 30, in isert_or_update
    self.cursor.execute(sql, param)
  File "D:\myPy\gpt\venv\Lib\site-packages\mysql\connector\cursor_cext.py", line 352, in execute
    raise ProgrammingError(
mysql.connector.errors.ProgrammingError: Not all parameters were used in the SQL statement
-------------------------------------------------------------        
[mysql_handler] [2024-09-05 10:07:39,350] [ERROR] > Error insert request: Not all parameters were used in the SQL statement
Traceback (most recent call last):
  File "D:\myPy\xboxshop\parser\mysql_handler.py", line 28, in isert_or_update
    self.cursor.execute(sql, param)
  File "D:\myPy\gpt\venv\Lib\site-packages\mysql\connector\cursor_cext.py", line 352, in execute
    raise ProgrammingError(
mysql.connector.errors.ProgrammingError: Not all parameters were used in the SQL statement
-------------------------------------------------------------        
[mysql_handler] [2024-09-05 10:07:54,474] [ERROR] > Error insert request: Not all parameters were used in the SQL statement
Traceback (most recent call last):
  File "D:\myPy\xboxshop\parser\mysql_handler.py", line 28, in isert_or_update
    self.cursor.execute(sql, param)
  File "D:\myPy\gpt\venv\Lib\site-packages\mysql\connector\cursor_cext.py", line 352, in execute
    raise ProgrammingError(
mysql.connector.errors.ProgrammingError: Not all parameters were used in the SQL statement
-------------------------------------------------------------        
[mysql_handler] [2024-09-05 10:17:44,594] [ERROR] > Error insert request: Not all parameters were used in the SQL statement
Traceback (most recent call last):
  File "D:\myPy\xboxshop\parser\mysql_handler.py", line 28, in isert_or_update
    self.cursor.execute(sql, param)
  File "D:\myPy\gpt\venv\Lib\site-packages\mysql\connector\cursor_cext.py", line 352, in execute
    raise ProgrammingError(
mysql.connector.errors.ProgrammingError: Not all parameters were used in the SQL statement
-------------------------------------------------------------        
[mysql_handler] [2024-09-05 10:18:28,248] [ERROR] > Error insert request: Not all parameters were used in the SQL statement
Traceback (most recent call last):
  File "D:\myPy\xboxshop\parser\mysql_handler.py", line 29, in isert_or_update
    self.cursor.execute(sql, param)
  File "D:\myPy\gpt\venv\Lib\site-packages\mysql\connector\cursor_cext.py", line 352, in execute
    raise ProgrammingError(
mysql.connector.errors.ProgrammingError: Not all parameters were used in the SQL statement
-------------------------------------------------------------        
[mysql_handler] [2024-09-05 10:20:24,703] [ERROR] > Error insert request: Not all parameters were used in the SQL statement
Traceback (most recent call last):
  File "D:\myPy\xboxshop\parser\mysql_handler.py", line 29, in isert_or_update
    self.cursor.execute(sql, param)
  File "D:\myPy\gpt\venv\Lib\site-packages\mysql\connector\cursor_cext.py", line 352, in execute
    raise ProgrammingError(
mysql.connector.errors.ProgrammingError: Not all parameters were used in the SQL statement
-------------------------------------------------------------        
[mysql_handler] [2024-09-05 19:12:41,264] [ERROR] > Error insert request: Not all parameters were used in the SQL statement
Traceback (most recent call last):
  File "D:\myPy\xboxshop\parser\mysql_handler.py", line 29, in isert_or_update
    self.cursor.execute(sql, param)
  File "D:\myPy\gpt\venv\Lib\site-packages\mysql\connector\cursor_cext.py", line 352, in execute
    raise ProgrammingError(
mysql.connector.errors.ProgrammingError: Not all parameters were used in the SQL statement
-------------------------------------------------------------        
[mysql_handler] [2024-09-10 23:43:46,626] [ERROR] > Error insert request: 1136 (21S01): Column count doesn't match value count at row 1
Traceback (most recent call last):
  File "D:\myPy\gpt\venv\Lib\site-packages\mysql\connector\connection_cext.py", line 705, in cmd_query
    self._cmysql.query(
_mysql_connector.MySQLInterfaceError: Column count doesn't match value count at row 1

The above exception was the direct cause of the following exception:

Traceback (most recent call last):
  File "D:\myPy\xboxshop\parser\mysql_handler.py", line 30, in isert_or_update
    self.cursor.execute(sql, param)
  File "D:\myPy\gpt\venv\Lib\site-packages\mysql\connector\cursor_cext.py", line 357, in execute
    result = self._connection.cmd_query(
             ^^^^^^^^^^^^^^^^^^^^^^^^^^^
  File "D:\myPy\gpt\venv\Lib\site-packages\mysql\connector\opentelemetry\context_propagation.py", line 97, in wrapper
    return method(cnx, *args, **kwargs)
           ^^^^^^^^^^^^^^^^^^^^^^^^^^^^
  File "D:\myPy\gpt\venv\Lib\site-packages\mysql\connector\connection_cext.py", line 713, in cmd_query
    raise get_mysql_exception(
mysql.connector.errors.DataError: 1136 (21S01): Column count doesn't match value count at row 1
-------------------------------------------------------------        
[mysql_handler] [2024-09-10 23:43:53,237] [ERROR] > Error insert request: 1136 (21S01): Column count doesn't match value count at row 1
Traceback (most recent call last):
  File "D:\myPy\gpt\venv\Lib\site-packages\mysql\connector\connection_cext.py", line 705, in cmd_query
    self._cmysql.query(
_mysql_connector.MySQLInterfaceError: Column count doesn't match value count at row 1

The above exception was the direct cause of the following exception:

Traceback (most recent call last):
  File "D:\myPy\xboxshop\parser\mysql_handler.py", line 30, in isert_or_update
    self.cursor.execute(sql, param)
  File "D:\myPy\gpt\venv\Lib\site-packages\mysql\connector\cursor_cext.py", line 357, in execute
    result = self._connection.cmd_query(
             ^^^^^^^^^^^^^^^^^^^^^^^^^^^
  File "D:\myPy\gpt\venv\Lib\site-packages\mysql\connector\opentelemetry\context_propagation.py", line 97, in wrapper
    return method(cnx, *args, **kwargs)
           ^^^^^^^^^^^^^^^^^^^^^^^^^^^^
  File "D:\myPy\gpt\venv\Lib\site-packages\mysql\connector\connection_cext.py", line 713, in cmd_query
    raise get_mysql_exception(
mysql.connector.errors.DataError: 1136 (21S01): Column count doesn't match value count at row 1
-------------------------------------------------------------        
[mysql_handler] [2024-09-10 23:47:16,078] [ERROR] > Error insert request: 1048 (23000): Column 'relise_date' cannot be null
Traceback (most recent call last):
  File "D:\myPy\gpt\venv\Lib\site-packages\mysql\connector\connection_cext.py", line 705, in cmd_query
    self._cmysql.query(
_mysql_connector.MySQLInterfaceError: Column 'relise_date' cannot be null

The above exception was the direct cause of the following exception:

Traceback (most recent call last):
  File "D:\myPy\xboxshop\parser\mysql_handler.py", line 30, in isert_or_update
    self.cursor.execute(sql, param)
  File "D:\myPy\gpt\venv\Lib\site-packages\mysql\connector\cursor_cext.py", line 357, in execute
    result = self._connection.cmd_query(
             ^^^^^^^^^^^^^^^^^^^^^^^^^^^
  File "D:\myPy\gpt\venv\Lib\site-packages\mysql\connector\opentelemetry\context_propagation.py", line 97, in wrapper
    return method(cnx, *args, **kwargs)
           ^^^^^^^^^^^^^^^^^^^^^^^^^^^^
  File "D:\myPy\gpt\venv\Lib\site-packages\mysql\connector\connection_cext.py", line 713, in cmd_query
    raise get_mysql_exception(
mysql.connector.errors.IntegrityError: 1048 (23000): Column 'relise_date' cannot be null
-------------------------------------------------------------        
[mysql_handler] [2024-09-10 23:47:23,562] [ERROR] > Error insert request: 1048 (23000): Column 'relise_date' cannot be null
Traceback (most recent call last):
  File "D:\myPy\gpt\venv\Lib\site-packages\mysql\connector\connection_cext.py", line 705, in cmd_query
    self._cmysql.query(
_mysql_connector.MySQLInterfaceError: Column 'relise_date' cannot be null

The above exception was the direct cause of the following exception:

Traceback (most recent call last):
  File "D:\myPy\xboxshop\parser\mysql_handler.py", line 30, in isert_or_update
    self.cursor.execute(sql, param)
  File "D:\myPy\gpt\venv\Lib\site-packages\mysql\connector\cursor_cext.py", line 357, in execute
    result = self._connection.cmd_query(
             ^^^^^^^^^^^^^^^^^^^^^^^^^^^
  File "D:\myPy\gpt\venv\Lib\site-packages\mysql\connector\opentelemetry\context_propagation.py", line 97, in wrapper
    return method(cnx, *args, **kwargs)
           ^^^^^^^^^^^^^^^^^^^^^^^^^^^^
  File "D:\myPy\gpt\venv\Lib\site-packages\mysql\connector\connection_cext.py", line 713, in cmd_query
    raise get_mysql_exception(
mysql.connector.errors.IntegrityError: 1048 (23000): Column 'relise_date' cannot be null
-------------------------------------------------------------        
[mysql_handler] [2024-09-11 22:04:49,586] [ERROR] > Error insert request: 1048 (23000): Column 'relise_date' cannot be null
Traceback (most recent call last):
  File "D:\myPy\gpt\venv\Lib\site-packages\mysql\connector\connection_cext.py", line 705, in cmd_query
    self._cmysql.query(
_mysql_connector.MySQLInterfaceError: Column 'relise_date' cannot be null

The above exception was the direct cause of the following exception:

Traceback (most recent call last):
  File "D:\myPy\xboxshop\parser\mysql_handler.py", line 30, in isert_or_update
    self.cursor.execute(sql, param)
  File "D:\myPy\gpt\venv\Lib\site-packages\mysql\connector\cursor_cext.py", line 357, in execute
    result = self._connection.cmd_query(
             ^^^^^^^^^^^^^^^^^^^^^^^^^^^
  File "D:\myPy\gpt\venv\Lib\site-packages\mysql\connector\opentelemetry\context_propagation.py", line 97, in wrapper
    return method(cnx, *args, **kwargs)
           ^^^^^^^^^^^^^^^^^^^^^^^^^^^^
  File "D:\myPy\gpt\venv\Lib\site-packages\mysql\connector\connection_cext.py", line 713, in cmd_query
    raise get_mysql_exception(
mysql.connector.errors.IntegrityError: 1048 (23000): Column 'relise_date' cannot be null
-------------------------------------------------------------        
[mysql_handler] [2024-09-11 22:04:56,446] [ERROR] > Error insert request: 1048 (23000): Column 'relise_date' cannot be null
Traceback (most recent call last):
  File "D:\myPy\gpt\venv\Lib\site-packages\mysql\connector\connection_cext.py", line 705, in cmd_query
    self._cmysql.query(
_mysql_connector.MySQLInterfaceError: Column 'relise_date' cannot be null

The above exception was the direct cause of the following exception:

Traceback (most recent call last):
  File "D:\myPy\xboxshop\parser\mysql_handler.py", line 30, in isert_or_update
    self.cursor.execute(sql, param)
  File "D:\myPy\gpt\venv\Lib\site-packages\mysql\connector\cursor_cext.py", line 357, in execute
    result = self._connection.cmd_query(
             ^^^^^^^^^^^^^^^^^^^^^^^^^^^
  File "D:\myPy\gpt\venv\Lib\site-packages\mysql\connector\opentelemetry\context_propagation.py", line 97, in wrapper
    return method(cnx, *args, **kwargs)
           ^^^^^^^^^^^^^^^^^^^^^^^^^^^^
  File "D:\myPy\gpt\venv\Lib\site-packages\mysql\connector\connection_cext.py", line 713, in cmd_query
    raise get_mysql_exception(
mysql.connector.errors.IntegrityError: 1048 (23000): Column 'relise_date' cannot be null
-------------------------------------------------------------        
[mysql_handler] [2024-09-11 22:06:15,089] [ERROR] > Error insert request: 1048 (23000): Column 'relise_date' cannot be null
Traceback (most recent call last):
  File "D:\myPy\gpt\venv\Lib\site-packages\mysql\connector\connection_cext.py", line 705, in cmd_query
    self._cmysql.query(
_mysql_connector.MySQLInterfaceError: Column 'relise_date' cannot be null

The above exception was the direct cause of the following exception:

Traceback (most recent call last):
  File "D:\myPy\xboxshop\parser\mysql_handler.py", line 30, in isert_or_update
    self.cursor.execute(sql, param)
  File "D:\myPy\gpt\venv\Lib\site-packages\mysql\connector\cursor_cext.py", line 357, in execute
    result = self._connection.cmd_query(
             ^^^^^^^^^^^^^^^^^^^^^^^^^^^
  File "D:\myPy\gpt\venv\Lib\site-packages\mysql\connector\opentelemetry\context_propagation.py", line 97, in wrapper
    return method(cnx, *args, **kwargs)
           ^^^^^^^^^^^^^^^^^^^^^^^^^^^^
  File "D:\myPy\gpt\venv\Lib\site-packages\mysql\connector\connection_cext.py", line 713, in cmd_query
    raise get_mysql_exception(
mysql.connector.errors.IntegrityError: 1048 (23000): Column 'relise_date' cannot be null
-------------------------------------------------------------        
[mysql_handler] [2024-09-11 22:06:21,533] [ERROR] > Error insert request: 1048 (23000): Column 'relise_date' cannot be null
Traceback (most recent call last):
  File "D:\myPy\gpt\venv\Lib\site-packages\mysql\connector\connection_cext.py", line 705, in cmd_query
    self._cmysql.query(
_mysql_connector.MySQLInterfaceError: Column 'relise_date' cannot be null

The above exception was the direct cause of the following exception:

Traceback (most recent call last):
  File "D:\myPy\xboxshop\parser\mysql_handler.py", line 30, in isert_or_update
    self.cursor.execute(sql, param)
  File "D:\myPy\gpt\venv\Lib\site-packages\mysql\connector\cursor_cext.py", line 357, in execute
    result = self._connection.cmd_query(
             ^^^^^^^^^^^^^^^^^^^^^^^^^^^
  File "D:\myPy\gpt\venv\Lib\site-packages\mysql\connector\opentelemetry\context_propagation.py", line 97, in wrapper
    return method(cnx, *args, **kwargs)
           ^^^^^^^^^^^^^^^^^^^^^^^^^^^^
  File "D:\myPy\gpt\venv\Lib\site-packages\mysql\connector\connection_cext.py", line 713, in cmd_query
    raise get_mysql_exception(
mysql.connector.errors.IntegrityError: 1048 (23000): Column 'relise_date' cannot be null
-------------------------------------------------------------        
[mysql_handler] [2024-09-11 22:08:35,237] [ERROR] > Error insert request: 1048 (23000): Column 'relise_date' cannot be null
Traceback (most recent call last):
  File "D:\myPy\gpt\venv\Lib\site-packages\mysql\connector\connection_cext.py", line 705, in cmd_query
    self._cmysql.query(
_mysql_connector.MySQLInterfaceError: Column 'relise_date' cannot be null

The above exception was the direct cause of the following exception:

Traceback (most recent call last):
  File "D:\myPy\xboxshop\parser\mysql_handler.py", line 30, in isert_or_update
    self.cursor.execute(sql, param)
  File "D:\myPy\gpt\venv\Lib\site-packages\mysql\connector\cursor_cext.py", line 357, in execute
    result = self._connection.cmd_query(
             ^^^^^^^^^^^^^^^^^^^^^^^^^^^
  File "D:\myPy\gpt\venv\Lib\site-packages\mysql\connector\opentelemetry\context_propagation.py", line 97, in wrapper
    return method(cnx, *args, **kwargs)
           ^^^^^^^^^^^^^^^^^^^^^^^^^^^^
  File "D:\myPy\gpt\venv\Lib\site-packages\mysql\connector\connection_cext.py", line 713, in cmd_query
    raise get_mysql_exception(
mysql.connector.errors.IntegrityError: 1048 (23000): Column 'relise_date' cannot be null
-------------------------------------------------------------        
[mysql_handler] [2024-09-11 22:12:08,570] [ERROR] > Error insert request: 1048 (23000): Column 'relise_date' cannot be null
Traceback (most recent call last):
  File "D:\myPy\gpt\venv\Lib\site-packages\mysql\connector\connection_cext.py", line 705, in cmd_query
    self._cmysql.query(
_mysql_connector.MySQLInterfaceError: Column 'relise_date' cannot be null

The above exception was the direct cause of the following exception:

Traceback (most recent call last):
  File "D:\myPy\xboxshop\parser\mysql_handler.py", line 30, in isert_or_update
    self.cursor.execute(sql, param)
  File "D:\myPy\gpt\venv\Lib\site-packages\mysql\connector\cursor_cext.py", line 357, in execute
    result = self._connection.cmd_query(
             ^^^^^^^^^^^^^^^^^^^^^^^^^^^
  File "D:\myPy\gpt\venv\Lib\site-packages\mysql\connector\opentelemetry\context_propagation.py", line 97, in wrapper
    return method(cnx, *args, **kwargs)
           ^^^^^^^^^^^^^^^^^^^^^^^^^^^^
  File "D:\myPy\gpt\venv\Lib\site-packages\mysql\connector\connection_cext.py", line 713, in cmd_query
    raise get_mysql_exception(
mysql.connector.errors.IntegrityError: 1048 (23000): Column 'relise_date' cannot be null
-------------------------------------------------------------        
[mysql_handler] [2024-09-11 23:23:58,721] [ERROR] > Error insert request: 1048 (23000): Column 'title' cannot be null
Traceback (most recent call last):
  File "D:\myPy\gpt\venv\Lib\site-packages\mysql\connector\connection_cext.py", line 705, in cmd_query
    self._cmysql.query(
_mysql_connector.MySQLInterfaceError: Column 'title' cannot be null

The above exception was the direct cause of the following exception:

Traceback (most recent call last):
  File "D:\myPy\xboxshop\parser\mysql_handler.py", line 30, in isert_or_update
    self.cursor.execute(sql, param)
  File "D:\myPy\gpt\venv\Lib\site-packages\mysql\connector\cursor_cext.py", line 357, in execute
    result = self._connection.cmd_query(
             ^^^^^^^^^^^^^^^^^^^^^^^^^^^
  File "D:\myPy\gpt\venv\Lib\site-packages\mysql\connector\opentelemetry\context_propagation.py", line 97, in wrapper
    return method(cnx, *args, **kwargs)
           ^^^^^^^^^^^^^^^^^^^^^^^^^^^^
  File "D:\myPy\gpt\venv\Lib\site-packages\mysql\connector\connection_cext.py", line 713, in cmd_query
    raise get_mysql_exception(
mysql.connector.errors.IntegrityError: 1048 (23000): Column 'title' cannot be null
-------------------------------------------------------------        
[mysql_handler] [2024-09-12 17:55:27,677] [ERROR] > Error insert request: 1048 (23000): Column 'title' cannot be null
Traceback (most recent call last):
  File "D:\myPy\gpt\venv\Lib\site-packages\mysql\connector\connection_cext.py", line 705, in cmd_query
    self._cmysql.query(
_mysql_connector.MySQLInterfaceError: Column 'title' cannot be null

The above exception was the direct cause of the following exception:

Traceback (most recent call last):
  File "D:\myPy\xboxshop\parser\mysql_handler.py", line 30, in isert_or_update
    self.cursor.execute(sql, param)
  File "D:\myPy\gpt\venv\Lib\site-packages\mysql\connector\cursor_cext.py", line 357, in execute
    result = self._connection.cmd_query(
             ^^^^^^^^^^^^^^^^^^^^^^^^^^^
  File "D:\myPy\gpt\venv\Lib\site-packages\mysql\connector\opentelemetry\context_propagation.py", line 97, in wrapper
    return method(cnx, *args, **kwargs)
           ^^^^^^^^^^^^^^^^^^^^^^^^^^^^
  File "D:\myPy\gpt\venv\Lib\site-packages\mysql\connector\connection_cext.py", line 713, in cmd_query
    raise get_mysql_exception(
mysql.connector.errors.IntegrityError: 1048 (23000): Column 'title' cannot be null
-------------------------------------------------------------        
[mysql_handler] [2024-09-12 19:32:29,576] [ERROR] > Error insert request: 1048 (23000): Column 'title' cannot be null
Traceback (most recent call last):
  File "D:\myPy\gpt\venv\Lib\site-packages\mysql\connector\connection_cext.py", line 705, in cmd_query
    self._cmysql.query(
_mysql_connector.MySQLInterfaceError: Column 'title' cannot be null

The above exception was the direct cause of the following exception:

Traceback (most recent call last):
  File "D:\myPy\xboxshop\parser\mysql_handler.py", line 30, in isert_or_update
    self.cursor.execute(sql, param)
  File "D:\myPy\gpt\venv\Lib\site-packages\mysql\connector\cursor_cext.py", line 357, in execute
    result = self._connection.cmd_query(
             ^^^^^^^^^^^^^^^^^^^^^^^^^^^
  File "D:\myPy\gpt\venv\Lib\site-packages\mysql\connector\opentelemetry\context_propagation.py", line 97, in wrapper
    return method(cnx, *args, **kwargs)
           ^^^^^^^^^^^^^^^^^^^^^^^^^^^^
  File "D:\myPy\gpt\venv\Lib\site-packages\mysql\connector\connection_cext.py", line 713, in cmd_query
    raise get_mysql_exception(
mysql.connector.errors.IntegrityError: 1048 (23000): Column 'title' cannot be null
-------------------------------------------------------------        
[mysql_handler] [2024-10-08 11:39:06,065] [ERROR] > Error insert request: 1048 (23000): Column 'title' cannot be null
Traceback (most recent call last):
  File "D:\myPy\gpt\venv\Lib\site-packages\mysql\connector\connection_cext.py", line 705, in cmd_query
    self._cmysql.query(
_mysql_connector.MySQLInterfaceError: Column 'title' cannot be null

The above exception was the direct cause of the following exception:

Traceback (most recent call last):
  File "D:\myPy\xboxshop\parser\mysql_handler.py", line 30, in isert_or_update
    self.cursor.execute(sql, param)
  File "D:\myPy\gpt\venv\Lib\site-packages\mysql\connector\cursor_cext.py", line 357, in execute
    result = self._connection.cmd_query(
             ^^^^^^^^^^^^^^^^^^^^^^^^^^^
  File "D:\myPy\gpt\venv\Lib\site-packages\mysql\connector\opentelemetry\context_propagation.py", line 97, in wrapper
    return method(cnx, *args, **kwargs)
           ^^^^^^^^^^^^^^^^^^^^^^^^^^^^
  File "D:\myPy\gpt\venv\Lib\site-packages\mysql\connector\connection_cext.py", line 713, in cmd_query
    raise get_mysql_exception(
mysql.connector.errors.IntegrityError: 1048 (23000): Column 'title' cannot be null
-------------------------------------------------------------        
[mysql_handler] [2024-10-08 11:39:13,524] [ERROR] > Error insert request: 1048 (23000): Column 'title' cannot be null
Traceback (most recent call last):
  File "D:\myPy\gpt\venv\Lib\site-packages\mysql\connector\connection_cext.py", line 705, in cmd_query
    self._cmysql.query(
_mysql_connector.MySQLInterfaceError: Column 'title' cannot be null

The above exception was the direct cause of the following exception:

Traceback (most recent call last):
  File "D:\myPy\xboxshop\parser\mysql_handler.py", line 30, in isert_or_update
    self.cursor.execute(sql, param)
  File "D:\myPy\gpt\venv\Lib\site-packages\mysql\connector\cursor_cext.py", line 357, in execute
    result = self._connection.cmd_query(
             ^^^^^^^^^^^^^^^^^^^^^^^^^^^
  File "D:\myPy\gpt\venv\Lib\site-packages\mysql\connector\opentelemetry\context_propagation.py", line 97, in wrapper
    return method(cnx, *args, **kwargs)
           ^^^^^^^^^^^^^^^^^^^^^^^^^^^^
  File "D:\myPy\gpt\venv\Lib\site-packages\mysql\connector\connection_cext.py", line 713, in cmd_query
    raise get_mysql_exception(
mysql.connector.errors.IntegrityError: 1048 (23000): Column 'title' cannot be null
-------------------------------------------------------------        
[mysql_handler] [2024-10-08 11:39:20,013] [ERROR] > Error insert request: 1048 (23000): Column 'title' cannot be null
Traceback (most recent call last):
  File "D:\myPy\gpt\venv\Lib\site-packages\mysql\connector\connection_cext.py", line 705, in cmd_query
    self._cmysql.query(
_mysql_connector.MySQLInterfaceError: Column 'title' cannot be null

The above exception was the direct cause of the following exception:

Traceback (most recent call last):
  File "D:\myPy\xboxshop\parser\mysql_handler.py", line 30, in isert_or_update
    self.cursor.execute(sql, param)
  File "D:\myPy\gpt\venv\Lib\site-packages\mysql\connector\cursor_cext.py", line 357, in execute
    result = self._connection.cmd_query(
             ^^^^^^^^^^^^^^^^^^^^^^^^^^^
  File "D:\myPy\gpt\venv\Lib\site-packages\mysql\connector\opentelemetry\context_propagation.py", line 97, in wrapper
    return method(cnx, *args, **kwargs)
           ^^^^^^^^^^^^^^^^^^^^^^^^^^^^
  File "D:\myPy\gpt\venv\Lib\site-packages\mysql\connector\connection_cext.py", line 713, in cmd_query
    raise get_mysql_exception(
mysql.connector.errors.IntegrityError: 1048 (23000): Column 'title' cannot be null
-------------------------------------------------------------        
[mysql_handler] [2024-10-08 11:39:33,783] [ERROR] > Error insert request: 1048 (23000): Column 'title' cannot be null
Traceback (most recent call last):
  File "D:\myPy\gpt\venv\Lib\site-packages\mysql\connector\connection_cext.py", line 705, in cmd_query
    self._cmysql.query(
_mysql_connector.MySQLInterfaceError: Column 'title' cannot be null

The above exception was the direct cause of the following exception:

Traceback (most recent call last):
  File "D:\myPy\xboxshop\parser\mysql_handler.py", line 30, in isert_or_update
    self.cursor.execute(sql, param)
  File "D:\myPy\gpt\venv\Lib\site-packages\mysql\connector\cursor_cext.py", line 357, in execute
    result = self._connection.cmd_query(
             ^^^^^^^^^^^^^^^^^^^^^^^^^^^
  File "D:\myPy\gpt\venv\Lib\site-packages\mysql\connector\opentelemetry\context_propagation.py", line 97, in wrapper
    return method(cnx, *args, **kwargs)
           ^^^^^^^^^^^^^^^^^^^^^^^^^^^^
  File "D:\myPy\gpt\venv\Lib\site-packages\mysql\connector\connection_cext.py", line 713, in cmd_query
    raise get_mysql_exception(
mysql.connector.errors.IntegrityError: 1048 (23000): Column 'title' cannot be null
-------------------------------------------------------------        
[mysql_handler] [2024-10-08 11:39:48,114] [ERROR] > Error insert request: 1048 (23000): Column 'title' cannot be null
Traceback (most recent call last):
  File "D:\myPy\gpt\venv\Lib\site-packages\mysql\connector\connection_cext.py", line 705, in cmd_query
    self._cmysql.query(
_mysql_connector.MySQLInterfaceError: Column 'title' cannot be null

The above exception was the direct cause of the following exception:

Traceback (most recent call last):
  File "D:\myPy\xboxshop\parser\mysql_handler.py", line 30, in isert_or_update
    self.cursor.execute(sql, param)
  File "D:\myPy\gpt\venv\Lib\site-packages\mysql\connector\cursor_cext.py", line 357, in execute
    result = self._connection.cmd_query(
             ^^^^^^^^^^^^^^^^^^^^^^^^^^^
  File "D:\myPy\gpt\venv\Lib\site-packages\mysql\connector\opentelemetry\context_propagation.py", line 97, in wrapper
    return method(cnx, *args, **kwargs)
           ^^^^^^^^^^^^^^^^^^^^^^^^^^^^
  File "D:\myPy\gpt\venv\Lib\site-packages\mysql\connector\connection_cext.py", line 713, in cmd_query
    raise get_mysql_exception(
mysql.connector.errors.IntegrityError: 1048 (23000): Column 'title' cannot be null
-------------------------------------------------------------        
[mysql_handler] [2024-10-08 11:41:03,333] [ERROR] > Error insert request: 1048 (23000): Column 'title' cannot be null
Traceback (most recent call last):
  File "D:\myPy\gpt\venv\Lib\site-packages\mysql\connector\connection_cext.py", line 705, in cmd_query
    self._cmysql.query(
_mysql_connector.MySQLInterfaceError: Column 'title' cannot be null

The above exception was the direct cause of the following exception:

Traceback (most recent call last):
  File "D:\myPy\xboxshop\parser\mysql_handler.py", line 30, in isert_or_update
    self.cursor.execute(sql, param)
  File "D:\myPy\gpt\venv\Lib\site-packages\mysql\connector\cursor_cext.py", line 357, in execute
    result = self._connection.cmd_query(
             ^^^^^^^^^^^^^^^^^^^^^^^^^^^
  File "D:\myPy\gpt\venv\Lib\site-packages\mysql\connector\opentelemetry\context_propagation.py", line 97, in wrapper
    return method(cnx, *args, **kwargs)
           ^^^^^^^^^^^^^^^^^^^^^^^^^^^^
  File "D:\myPy\gpt\venv\Lib\site-packages\mysql\connector\connection_cext.py", line 713, in cmd_query
    raise get_mysql_exception(
mysql.connector.errors.IntegrityError: 1048 (23000): Column 'title' cannot be null
-------------------------------------------------------------        
[mysql_handler] [2024-10-08 11:41:08,748] [ERROR] > Error insert request: 1048 (23000): Column 'title' cannot be null
Traceback (most recent call last):
  File "D:\myPy\gpt\venv\Lib\site-packages\mysql\connector\connection_cext.py", line 705, in cmd_query
    self._cmysql.query(
_mysql_connector.MySQLInterfaceError: Column 'title' cannot be null

The above exception was the direct cause of the following exception:

Traceback (most recent call last):
  File "D:\myPy\xboxshop\parser\mysql_handler.py", line 30, in isert_or_update
    self.cursor.execute(sql, param)
  File "D:\myPy\gpt\venv\Lib\site-packages\mysql\connector\cursor_cext.py", line 357, in execute
    result = self._connection.cmd_query(
             ^^^^^^^^^^^^^^^^^^^^^^^^^^^
  File "D:\myPy\gpt\venv\Lib\site-packages\mysql\connector\opentelemetry\context_propagation.py", line 97, in wrapper
    return method(cnx, *args, **kwargs)
           ^^^^^^^^^^^^^^^^^^^^^^^^^^^^
  File "D:\myPy\gpt\venv\Lib\site-packages\mysql\connector\connection_cext.py", line 713, in cmd_query
    raise get_mysql_exception(
mysql.connector.errors.IntegrityError: 1048 (23000): Column 'title' cannot be null
-------------------------------------------------------------        
[mysql_handler] [2024-10-08 11:41:19,175] [ERROR] > Error insert request: 1048 (23000): Column 'title' cannot be null
Traceback (most recent call last):
  File "D:\myPy\gpt\venv\Lib\site-packages\mysql\connector\connection_cext.py", line 705, in cmd_query
    self._cmysql.query(
_mysql_connector.MySQLInterfaceError: Column 'title' cannot be null

The above exception was the direct cause of the following exception:

Traceback (most recent call last):
  File "D:\myPy\xboxshop\parser\mysql_handler.py", line 30, in isert_or_update
    self.cursor.execute(sql, param)
  File "D:\myPy\gpt\venv\Lib\site-packages\mysql\connector\cursor_cext.py", line 357, in execute
    result = self._connection.cmd_query(
             ^^^^^^^^^^^^^^^^^^^^^^^^^^^
  File "D:\myPy\gpt\venv\Lib\site-packages\mysql\connector\opentelemetry\context_propagation.py", line 97, in wrapper
    return method(cnx, *args, **kwargs)
           ^^^^^^^^^^^^^^^^^^^^^^^^^^^^
  File "D:\myPy\gpt\venv\Lib\site-packages\mysql\connector\connection_cext.py", line 713, in cmd_query
    raise get_mysql_exception(
mysql.connector.errors.IntegrityError: 1048 (23000): Column 'title' cannot be null
-------------------------------------------------------------        
[mysql_handler] [2024-10-08 11:41:24,890] [ERROR] > Error insert request: 1048 (23000): Column 'title' cannot be null
Traceback (most recent call last):
  File "D:\myPy\gpt\venv\Lib\site-packages\mysql\connector\connection_cext.py", line 705, in cmd_query
    self._cmysql.query(
_mysql_connector.MySQLInterfaceError: Column 'title' cannot be null

The above exception was the direct cause of the following exception:

Traceback (most recent call last):
  File "D:\myPy\xboxshop\parser\mysql_handler.py", line 30, in isert_or_update
    self.cursor.execute(sql, param)
  File "D:\myPy\gpt\venv\Lib\site-packages\mysql\connector\cursor_cext.py", line 357, in execute
    result = self._connection.cmd_query(
             ^^^^^^^^^^^^^^^^^^^^^^^^^^^
  File "D:\myPy\gpt\venv\Lib\site-packages\mysql\connector\opentelemetry\context_propagation.py", line 97, in wrapper
    return method(cnx, *args, **kwargs)
           ^^^^^^^^^^^^^^^^^^^^^^^^^^^^
  File "D:\myPy\gpt\venv\Lib\site-packages\mysql\connector\connection_cext.py", line 713, in cmd_query
    raise get_mysql_exception(
mysql.connector.errors.IntegrityError: 1048 (23000): Column 'title' cannot be null
-------------------------------------------------------------        
[mysql_handler] [2024-10-12 12:23:20,904] [ERROR] > Error update request
-------------------------------------------------------------        
[mysql_handler] [2024-10-12 12:31:25,547] [ERROR] > Error update request
-------------------------------------------------------------        
[mysql_handler] [2024-10-12 12:34:14,699] [ERROR] > Error update_rubles_per_lira: Not all parameters were used in the SQL statement
Traceback (most recent call last):
  File "D:\myPy\xboxshop\parser\mysql_handler.py", line 53, in update_rubles_per_lira
    self.cursor.execute(sql, param)
  File "D:\myPy\gpt\venv\Lib\site-packages\mysql\connector\cursor_cext.py", line 352, in execute
    raise ProgrammingError(
mysql.connector.errors.ProgrammingError: Not all parameters were used in the SQL statement
-------------------------------------------------------------        
[mysql_handler] [2024-10-14 19:02:34,258] [ERROR] > Error update_rubles_per_lira: Not all parameters were used in the SQL statement
Traceback (most recent call last):
  File "D:\myPy\xboxshop\parser\mysql_handler.py", line 53, in update_rubles_per_lira
    self.cursor.execute(sql, param)
  File "D:\myPy\gpt\venv\Lib\site-packages\mysql\connector\cursor_cext.py", line 352, in execute
    raise ProgrammingError(
mysql.connector.errors.ProgrammingError: Not all parameters were used in the SQL statement
-------------------------------------------------------------        
[mysql_handler] [2024-10-14 19:05:28,229] [ERROR] > Error update_rubles_per_lira: Not all parameters were used in the SQL statement
Traceback (most recent call last):
  File "D:\myPy\xboxshop\parser\mysql_handler.py", line 53, in update_rubles_per_lira
    self.cursor.execute(sql, param)
  File "D:\myPy\gpt\venv\Lib\site-packages\mysql\connector\cursor_cext.py", line 352, in execute
    raise ProgrammingError(
mysql.connector.errors.ProgrammingError: Not all parameters were used in the SQL statement
-------------------------------------------------------------        
[mysql_handler] [2024-10-14 19:07:33,182] [ERROR] > Error update_rubles_per_lira: Not all parameters were used in the SQL statement
Traceback (most recent call last):
  File "D:\myPy\xboxshop\parser\mysql_handler.py", line 53, in update_rubles_per_lira
    self.cursor.execute(sql, param)
  File "D:\myPy\gpt\venv\Lib\site-packages\mysql\connector\cursor_cext.py", line 352, in execute
    raise ProgrammingError(
mysql.connector.errors.ProgrammingError: Not all parameters were used in the SQL statement
-------------------------------------------------------------        
[mysql_handler] [2024-10-14 19:11:19,300] [ERROR] > Error update_rubles_per_lira: 1146 (42S02): Table 'xbox_store.course_tur_lira' doesn't exist
Traceback (most recent call last):
  File "D:\myPy\gpt\venv\Lib\site-packages\mysql\connector\connection_cext.py", line 705, in cmd_query
    self._cmysql.query(
_mysql_connector.MySQLInterfaceError: Table 'xbox_store.course_tur_lira' doesn't exist

The above exception was the direct cause of the following exception:

Traceback (most recent call last):
  File "D:\myPy\xboxshop\parser\mysql_handler.py", line 53, in update_rubles_per_lira
    self.cursor.execute(sql, param)
  File "D:\myPy\gpt\venv\Lib\site-packages\mysql\connector\cursor_cext.py", line 357, in execute
    result = self._connection.cmd_query(
             ^^^^^^^^^^^^^^^^^^^^^^^^^^^
  File "D:\myPy\gpt\venv\Lib\site-packages\mysql\connector\opentelemetry\context_propagation.py", line 97, in wrapper
    return method(cnx, *args, **kwargs)
           ^^^^^^^^^^^^^^^^^^^^^^^^^^^^
  File "D:\myPy\gpt\venv\Lib\site-packages\mysql\connector\connection_cext.py", line 713, in cmd_query
    raise get_mysql_exception(
mysql.connector.errors.ProgrammingError: 1146 (42S02): Table 'xbox_store.course_tur_lira' doesn't exist
